Workbook

Sheet Summary Metrics
A1: Task 5: Experiment Summary - Control vs Treatment
A3: Metric | B3: Required Calculation | C3: Control | D3: Treatment | E3: Difference (Treatment - Control) | F3: Simple Interpretation
A4: User Count | B4: Number of users in each group | C4: =COUNTIF('Raw Data'!$C:$C,"Control") | D4: =COUNTIF('Raw Data'!$C:$C,"Treatment") | E4: =D4-C4 | F4: Treatment has slightly more users
A5: Landing Page Visit Rate | B5: Users who visited landing page / total users | C5: =COUNTIFS('Raw Data'!$C:$C,"Control",'Raw Data'!$H:$H,1)/C4 | D5: =COUNTIFS('Raw Data'!$C:$C,"Treatment",'Raw Data'!$H:$H,1)/D4 | E5: =D5-C5 | F5: Higher rate is better
A6: Trial Start Rate | B6: Users who started trial / total users | C6: =COUNTIFS('Raw Data'!$C:$C,"Control",'Raw Data'!$I:$I,1)/C4 | D6: =COUNTIFS('Raw Data'!$C:$C,"Treatment",'Raw Data'!$I:$I,1)/D4 | E6: =D6-C6 | F6: Higher rate is better
A7: Onboarding Completion Rate | B7: Users who completed onboarding / total users | C7: =COUNTIFS('Raw Data'!$C:$C,"Control",'Raw Data'!$J:$J,1)/C4 | D7: =COUNTIFS('Raw Data'!$C:$C,"Treatment",'Raw Data'!$J:$J,1)/D4 | E7: =D7-C7 | F7: Higher rate is better
A8: Paid Conversion Rate | B8: Users converted to paid / total users | C8: =COUNTIFS('Raw Data'!$C:$C,"Control",'Raw Data'!$K:$K,1)/C4 | D8: =COUNTIFS('Raw Data'!$C:$C,"Treatment",'Raw Data'!$K:$K,1)/D4 | E8: =D8-C8 | F8: This is the North Star Metric
A9: Average Revenue Per User | B9: Total revenue / total users | C9: =SUMIFS('Raw Data'!$L:$L,'Raw Data'!$C:$C,"Control")/C4 | D9: =SUMIFS('Raw Data'!$L:$L,'Raw Data'!$C:$C,"Treatment")/D4 | E9: =D9-C9 | F9: Higher ARPU is better
A10: Average Revenue Per Converted User | B10: Revenue / converted users | C10: =IFERROR(SUMIFS('Raw Data'!$L:$L,'Raw Data'!$C:$C,"Control")/COUNTIFS('Raw Data'!$C:$C,"Control",'Raw Data'!$K:$K,1),0) | D10: =IFERROR(SUMIFS('Raw Data'!$L:$L,'Raw Data'!$C:$C,"Treatment")/COUNTIFS('Raw Data'!$C:$C,"Treatment",'Raw Data'!$K:$K,1),0) | E10: =D10-C10 | F10: Shows revenue quality of converted users
A11: Refund Rate | B11: Refund requests / total users | C11: =COUNTIFS('Raw Data'!$C:$C,"Control",'Raw Data'!$N:$N,1)/C4 | D11: =COUNTIFS('Raw Data'!$C:$C,"Treatment",'Raw Data'!$N:$N,1)/D4 | E11: =D11-C11 | F11: Lower rate is better
A12: Support Ticket Rate | B12: Users with support tickets / total users | C12: =COUNTIFS('Raw Data'!$C:$C,"Control",'Raw Data'!$M:$M,">0")/C4 | D12: =COUNTIFS('Raw Data'!$C:$C,"Treatment",'Raw Data'!$M:$M,">0")/D4 | E12: =D12-C12 | F12: Lower rate is better
A13: Average Engagement Score | B13: Average score by group | C13: =AVERAGEIFS('Raw Data'!$P:$P,'Raw Data'!$C:$C,"Control") | D13: =AVERAGEIFS('Raw Data'!$P:$P,'Raw Data'!$C:$C,"Treatment") | E13: =D13-C13 | F13: Higher engagement is better
A14: Average Days To Convert | B14: Average days for users who converted | C14: =AVERAGEIFS('Raw Data'!$O:$O,'Raw Data'!$C:$C,"Control",'Raw Data'!$K:$K,1) | D14: =AVERAGEIFS('Raw Data'!$O:$O,'Raw Data'!$C:$C,"Treatment",'Raw Data'!$K:$K,1) | E14: =D14-C14 | F14: Lower days is better
A17: Student Note
A18: This sheet compares the Control and Treatment groups across main success metrics and guardrail metrics. Paid Conversion Rate is the North Star Metric for this experiment.

Sheet Region Analysis
A1: Region Analysis - Segment Level Metrics
A3: Region | B3: Control Users | C3: Treatment Users | D3: Control Paid Conversion Rate | E3: Treatment Paid Conversion Rate | F3: Control ARPU | G3: Treatment ARPU | H3: Control Avg Engagement | I3: Treatment Avg Engagement | J3: Quick Comment
A4: East | B4: =COUNTIFS('Raw Data'!$C:$C,"Control",'Raw Data'!$D:$D,"East") | C4: =COUNTIFS('Raw Data'!$C:$C,"Treatment",'Raw Data'!$D:$D,"East") | D4: =IFERROR(COUNTIFS('Raw Data'!$C:$C,"Control",'Raw Data'!$D:$D,"East",'Raw Data'!$K:$K,1)/B4,0) | E4: =IFERROR(COUNTIFS('Raw Data'!$C:$C,"Treatment",'Raw Data'!$D:$D,"East",'Raw Data'!$K:$K,1)/C4,0) | F4: =IFERROR(SUMIFS('Raw Data'!$L:$L,'Raw Data'!$C:$C,"Control",'Raw Data'!$D:$D,"East")/B4,0) | G4: =IFERROR(SUMIFS('Raw Data'!$L:$L,'Raw Data'!$C:$C,"Treatment",'Raw Data'!$D:$D,"East")/C4,0) | H4: =IFERROR(AVERAGEIFS('Raw Data'!$P:$P,'Raw Data'!$C:$C,"Control",'Raw Data'!$D:$D,"East"),0) | I4: =IFERROR(AVERAGEIFS('Raw Data'!$P:$P,'Raw Data'!$C:$C,"Treatment",'Raw Data'!$D:$D,"East"),0) | J4: =IF(E4>D4,"Treatment better conversion","Control better/equal conversion")
A5: North | B5: =COUNTIFS('Raw Data'!$C:$C,"Control",'Raw Data'!$D:$D,"North") | C5: =COUNTIFS('Raw Data'!$C:$C,"Treatment",'Raw Data'!$D:$D,"North") | D5: =IFERROR(COUNTIFS('Raw Data'!$C:$C,"Control",'Raw Data'!$D:$D,"North",'Raw Data'!$K:$K,1)/B5,0) | E5: =IFERROR(COUNTIFS('Raw Data'!$C:$C,"Treatment",'Raw Data'!$D:$D,"North",'Raw Data'!$K:$K,1)/C5,0) | F5: =IFERROR(SUMIFS('Raw Data'!$L:$L,'Raw Data'!$C:$C,"Control",'Raw Data'!$D:$D,"North")/B5,0) | G5: =IFERROR(SUMIFS('Raw Data'!$L:$L,'Raw Data'!$C:$C,"Treatment",'Raw Data'!$D:$D,"North")/C5,0) | H5: =IFERROR(AVERAGEIFS('Raw Data'!$P:$P,'Raw Data'!$C:$C,"Control",'Raw Data'!$D:$D,"North"),0) | I5: =IFERROR(AVERAGEIFS('Raw Data'!$P:$P,'Raw Data'!$C:$C,"Treatment",'Raw Data'!$D:$D,"North"),0) | J5: =IF(E5>D5,"Treatment better conversion","Control better/equal conversion")
A6: South | B6: =COUNTIFS('Raw Data'!$C:$C,"Control",'Raw Data'!$D:$D,"South") | C6: =COUNTIFS('Raw Data'!$C:$C,"Treatment",'Raw Data'!$D:$D,"South") | D6: =IFERROR(COUNTIFS('Raw Data'!$C:$C,"Control",'Raw Data'!$D:$D,"South",'Raw Data'!$K:$K,1)/B6,0) | E6: =IFERROR(COUNTIFS('Raw Data'!$C:$C,"Treatment",'Raw Data'!$D:$D,"South",'Raw Data'!$K:$K,1)/C6,0) | F6: =IFERROR(SUMIFS('Raw Data'!$L:$L,'Raw Data'!$C:$C,"Control",'Raw Data'!$D:$D,"South")/B6,0) | G6: =IFERROR(SUMIFS('Raw Data'!$L:$L,'Raw Data'!$C:$C,"Treatment",'Raw Data'!$D:$D,"South")/C6,0) | H6: =IFERROR(AVERAGEIFS('Raw Data'!$P:$P,'Raw Data'!$C:$C,"Control",'Raw Data'!$D:$D,"South"),0) | I6: =IFERROR(AVERAGEIFS('Raw Data'!$P:$P,'Raw Data'!$C:$C,"Treatment",'Raw Data'!$D:$D,"South"),0) | J6: =IF(E6>D6,"Treatment better conversion","Control better/equal conversion")
A7: West | B7: =COUNTIFS('Raw Data'!$C:$C,"Control",'Raw Data'!$D:$D,"West") | C7: =COUNTIFS('Raw Data'!$C:$C,"Treatment",'Raw Data'!$D:$D,"West") | D7: =IFERROR(COUNTIFS('Raw Data'!$C:$C,"Control",'Raw Data'!$D:$D,"West",'Raw Data'!$K:$K,1)/B7,0) | E7: =IFERROR(COUNTIFS('Raw Data'!$C:$C,"Treatment",'Raw Data'!$D:$D,"West",'Raw Data'!$K:$K,1)/C7,0) | F7: =IFERROR(SUMIFS('Raw Data'!$L:$L,'Raw Data'!$C:$C,"Control",'Raw Data'!$D:$D,"West")/B7,0) | G7: =IFERROR(SUMIFS('Raw Data'!$L:$L,'Raw Data'!$C:$C,"Treatment",'Raw Data'!$D:$D,"West")/C7,0) | H7: =IFERROR(AVERAGEIFS('Raw Data'!$P:$P,'Raw Data'!$C:$C,"Control",'Raw Data'!$D:$D,"West"),0) | I7: =IFERROR(AVERAGEIFS('Raw Data'!$P:$P,'Raw Data'!$C:$C,"Treatment",'Raw Data'!$D:$D,"West"),0) | J7: =IF(E7>D7,"Treatment better conversion","Control better/equal conversion")
A10: Student Note
A11: This segment sheet compares at least three metrics by group: paid conversion rate, average revenue per user, and average engagement score.

Sheet Device Analysis
A1: Device Analysis - Segment Level Metrics
A3: Device Type | B3: Control Users | C3: Treatment Users | D3: Control Paid Conversion Rate | E3: Treatment Paid Conversion Rate | F3: Control ARPU | G3: Treatment ARPU | H3: Control Avg Engagement | I3: Treatment Avg Engagement | J3: Quick Comment
A4: (Missing) | B4: =COUNTIFS('Raw Data'!$C:$C,"Control",'Raw Data'!$E:$E,"") | C4: =COUNTIFS('Raw Data'!$C:$C,"Treatment",'Raw Data'!$E:$E,"") | D4: =IFERROR(COUNTIFS('Raw Data'!$C:$C,"Control",'Raw Data'!$E:$E,"",'Raw Data'!$K:$K,1)/B4,0) | E4: =IFERROR(COUNTIFS('Raw Data'!$C:$C,"Treatment",'Raw Data'!$E:$E,"",'Raw Data'!$K:$K,1)/C4,0) | F4: =IFERROR(SUMIFS('Raw Data'!$L:$L,'Raw Data'!$C:$C,"Control",'Raw Data'!$E:$E,"")/B4,0) | G4: =IFERROR(SUMIFS('Raw Data'!$L:$L,'Raw Data'!$C:$C,"Treatment",'Raw Data'!$E:$E,"")/C4,0) | H4: =IFERROR(AVERAGEIFS('Raw Data'!$P:$P,'Raw Data'!$C:$C,"Control",'Raw Data'!$E:$E,""),0) | I4: =IFERROR(AVERAGEIFS('Raw Data'!$P:$P,'Raw Data'!$C:$C,"Treatment",'Raw Data'!$E:$E,""),0) | J4: =IF(E4>D4,"Treatment better conversion","Control better/equal conversion")
A5: Desktop | B5: =COUNTIFS('Raw Data'!$C:$C,"Control",'Raw Data'!$E:$E,"Desktop") | C5: =COUNTIFS('Raw Data'!$C:$C,"Treatment",'Raw Data'!$E:$E,"Desktop") | D5: =IFERROR(COUNTIFS('Raw Data'!$C:$C,"Control",'Raw Data'!$E:$E,"Desktop",'Raw Data'!$K:$K,1)/B5,0) | E5: =IFERROR(COUNTIFS('Raw Data'!$C:$C,"Treatment",'Raw Data'!$E:$E,"Desktop",'Raw Data'!$K:$K,1)/C5,0) | F5: =IFERROR(SUMIFS('Raw Data'!$L:$L,'Raw Data'!$C:$C,"Control",'Raw Data'!$E:$E,"Desktop")/B5,0) | G5: =IFERROR(SUMIFS('Raw Data'!$L:$L,'Raw Data'!$C:$C,"Treatment",'Raw Data'!$E:$E,"Desktop")/C5,0) | H5: =IFERROR(AVERAGEIFS('Raw Data'!$P:$P,'Raw Data'!$C:$C,"Control",'Raw Data'!$E:$E,"Desktop"),0) | I5: =IFERROR(AVERAGEIFS('Raw Data'!$P:$P,'Raw Data'!$C:$C,"Treatment",'Raw Data'!$E:$E,"Desktop"),0) | J5: =IF(E5>D5,"Treatment better conversion","Control better/equal conversion")
A6: Mobile | B6: =COUNTIFS('Raw Data'!$C:$C,"Control",'Raw Data'!$E:$E,"Mobile") | C6: =COUNTIFS('Raw Data'!$C:$C,"Treatment",'Raw Data'!$E:$E,"Mobile") | D6: =IFERROR(COUNTIFS('Raw Data'!$C:$C,"Control",'Raw Data'!$E:$E,"Mobile",'Raw Data'!$K:$K,1)/B6,0) | E6: =IFERROR(COUNTIFS('Raw Data'!$C:$C,"Treatment",'Raw Data'!$E:$E,"Mobile",'Raw Data'!$K:$K,1)/C6,0) | F6: =IFERROR(SUMIFS('Raw Data'!$L:$L,'Raw Data'!$C:$C,"Control",'Raw Data'!$E:$E,"Mobile")/B6,0) | G6: =IFERROR(SUMIFS('Raw Data'!$L:$L,'Raw Data'!$C:$C,"Treatment",'Raw Data'!$E:$E,"Mobile")/C6,0) | H6: =IFERROR(AVERAGEIFS('Raw Data'!$P:$P,'Raw Data'!$C:$C,"Control",'Raw Data'!$E:$E,"Mobile"),0) | I6: =IFERROR(AVERAGEIFS('Raw Data'!$P:$P,'Raw Data'!$C:$C,"Treatment",'Raw Data'!$E:$E,"Mobile"),0) | J6: =IF(E6>D6,"Treatment better conversion","Control better/equal conversion")
A7: Tablet | B7: =COUNTIFS('Raw Data'!$C:$C,"Control",'Raw Data'!$E:$E,"Tablet") | C7: =COUNTIFS('Raw Data'!$C:$C,"Treatment",'Raw Data'!$E:$E,"Tablet") | D7: =IFERROR(COUNTIFS('Raw Data'!$C:$C,"Control",'Raw Data'!$E:$E,"Tablet",'Raw Data'!$K:$K,1)/B7,0) | E7: =IFERROR(COUNTIFS('Raw Data'!$C:$C,"Treatment",'Raw Data'!$E:$E,"Tablet",'Raw Data'!$K:$K,1)/C7,0) | F7: =IFERROR(SUMIFS('Raw Data'!$L:$L,'Raw Data'!$C:$C,"Control",'Raw Data'!$E:$E,"Tablet")/B7,0) | G7: =IFERROR(SUMIFS('Raw Data'!$L:$L,'Raw Data'!$C:$C,"Treatment",'Raw Data'!$E:$E,"Tablet")/C7,0) | H7: =IFERROR(AVERAGEIFS('Raw Data'!$P:$P,'Raw Data'!$C:$C,"Control",'Raw Data'!$E:$E,"Tablet"),0) | I7: =IFERROR(AVERAGEIFS('Raw Data'!$P:$P,'Raw Data'!$C:$C,"Treatment",'Raw Data'!$E:$E,"Tablet"),0) | J7: =IF(E7>D7,"Treatment better conversion","Control better/equal conversion")
A10: Student Note
A11: This segment sheet compares at least three metrics by group: paid conversion rate, average revenue per user, and average engagement score.

Sheet Traffic Source Analysis
A1: Traffic Source Analysis - Segment Level Metrics
A3: Traffic Source | B3: Control Users | C3: Treatment Users | D3: Control Paid Conversion Rate | E3: Treatment Paid Conversion Rate | F3: Control ARPU | G3: Treatment ARPU | H3: Control Avg Engagement | I3: Treatment Avg Engagement | J3: Quick Comment
A4: (Missing) | B4: =COUNTIFS('Raw Data'!$C:$C,"Control",'Raw Data'!$F:$F,"") | C4: =COUNTIFS('Raw Data'!$C:$C,"Treatment",'Raw Data'!$F:$F,"") | D4: =IFERROR(COUNTIFS('Raw Data'!$C:$C,"Control",'Raw Data'!$F:$F,"",'Raw Data'!$K:$K,1)/B4,0) | E4: =IFERROR(COUNTIFS('Raw Data'!$C:$C,"Treatment",'Raw Data'!$F:$F,"",'Raw Data'!$K:$K,1)/C4,0) | F4: =IFERROR(SUMIFS('Raw Data'!$L:$L,'Raw Data'!$C:$C,"Control",'Raw Data'!$F:$F,"")/B4,0) | G4: =IFERROR(SUMIFS('Raw Data'!$L:$L,'Raw Data'!$C:$C,"Treatment",'Raw Data'!$F:$F,"")/C4,0) | H4: =IFERROR(AVERAGEIFS('Raw Data'!$P:$P,'Raw Data'!$C:$C,"Control",'Raw Data'!$F:$F,""),0) | I4: =IFERROR(AVERAGEIFS('Raw Data'!$P:$P,'Raw Data'!$C:$C,"Treatment",'Raw Data'!$F:$F,""),0) | J4: =IF(E4>D4,"Treatment better conversion","Control better/equal conversion")
A5: Email | B5: =COUNTIFS('Raw Data'!$C:$C,"Control",'Raw Data'!$F:$F,"Email") | C5: =COUNTIFS('Raw Data'!$C:$C,"Treatment",'Raw Data'!$F:$F,"Email") | D5: =IFERROR(COUNTIFS('Raw Data'!$C:$C,"Control",'Raw Data'!$F:$F,"Email",'Raw Data'!$K:$K,1)/B5,0) | E5: =IFERROR(COUNTIFS('Raw Data'!$C:$C,"Treatment",'Raw Data'!$F:$F,"Email",'Raw Data'!$K:$K,1)/C5,0) | F5: =IFERROR(SUMIFS('Raw Data'!$L:$L,'Raw Data'!$C:$C,"Control",'Raw Data'!$F:$F,"Email")/B5,0) | G5: =IFERROR(SUMIFS('Raw Data'!$L:$L,'Raw Data'!$C:$C,"Treatment",'Raw Data'!$F:$F,"Email")/C5,0) | H5: =IFERROR(AVERAGEIFS('Raw Data'!$P:$P,'Raw Data'!$C:$C,"Control",'Raw Data'!$F:$F,"Email"),0) | I5: =IFERROR(AVERAGEIFS('Raw Data'!$P:$P,'Raw Data'!$C:$C,"Treatment",'Raw Data'!$F:$F,"Email"),0) | J5: =IF(E5>D5,"Treatment better conversion","Control better/equal conversion")
A6: Organic | B6: =COUNTIFS('Raw Data'!$C:$C,"Control",'Raw Data'!$F:$F,"Organic") | C6: =COUNTIFS('Raw Data'!$C:$C,"Treatment",'Raw Data'!$F:$F,"Organic") | D6: =IFERROR(COUNTIFS('Raw Data'!$C:$C,"Control",'Raw Data'!$F:$F,"Organic",'Raw Data'!$K:$K,1)/B6,0) | E6: =IFERROR(COUNTIFS('Raw Data'!$C:$C,"Treatment",'Raw Data'!$F:$F,"Organic",'Raw Data'!$K:$K,1)/C6,0) | F6: =IFERROR(SUMIFS('Raw Data'!$L:$L,'Raw Data'!$C:$C,"Control",'Raw Data'!$F:$F,"Organic")/B6,0) | G6: =IFERROR(SUMIFS('Raw Data'!$L:$L,'Raw Data'!$C:$C,"Treatment",'Raw Data'!$F:$F,"Organic")/C6,0) | H6: =IFERROR(AVERAGEIFS('Raw Data'!$P:$P,'Raw Data'!$C:$C,"Control",'Raw Data'!$F:$F,"Organic"),0) | I6: =IFERROR(AVERAGEIFS('Raw Data'!$P:$P,'Raw Data'!$C:$C,"Treatment",'Raw Data'!$F:$F,"Organic"),0) | J6: =IF(E6>D6,"Treatment better conversion","Control better/equal conversion")
A7: Paid Search | B7: =COUNTIFS('Raw Data'!$C:$C,"Control",'Raw Data'!$F:$F,"Paid Search") | C7: =COUNTIFS('Raw Data'!$C:$C,"Treatment",'Raw Data'!$F:$F,"Paid Search") | D7: =IFERROR(COUNTIFS('Raw Data'!$C:$C,"Control",'Raw Data'!$F:$F,"Paid Search",'Raw Data'!$K:$K,1)/B7,0) | E7: =IFERROR(COUNTIFS('Raw Data'!$C:$C,"Treatment",'Raw Data'!$F:$F,"Paid Search",'Raw Data'!$K:$K,1)/C7,0) | F7: =IFERROR(SUMIFS('Raw Data'!$L:$L,'Raw Data'!$C:$C,"Control",'Raw Data'!$F:$F,"Paid Search")/B7,0) | G7: =IFERROR(SUMIFS('Raw Data'!$L:$L,'Raw Data'!$C:$C,"Treatment",'Raw Data'!$F:$F,"Paid Search")/C7,0) | H7: =IFERROR(AVERAGEIFS('Raw Data'!$P:$P,'Raw Data'!$C:$C,"Control",'Raw Data'!$F:$F,"Paid Search"),0) | I7: =IFERROR(AVERAGEIFS('Raw Data'!$P:$P,'Raw Data'!$C:$C,"Treatment",'Raw Data'!$F:$F,"Paid Search"),0) | J7: =IF(E7>D7,"Treatment better conversion","Control better/equal conversion")
A8: Referral | B8: =COUNTIFS('Raw Data'!$C:$C,"Control",'Raw Data'!$F:$F,"Referral") | C8: =COUNTIFS('Raw Data'!$C:$C,"Treatment",'Raw Data'!$F:$F,"Referral") | D8: =IFERROR(COUNTIFS('Raw Data'!$C:$C,"Control",'Raw Data'!$F:$F,"Referral",'Raw Data'!$K:$K,1)/B8,0) | E8: =IFERROR(COUNTIFS('Raw Data'!$C:$C,"Treatment",'Raw Data'!$F:$F,"Referral",'Raw Data'!$K:$K,1)/C8,0) | F8: =IFERROR(SUMIFS('Raw Data'!$L:$L,'Raw Data'!$C:$C,"Control",'Raw Data'!$F:$F,"Referral")/B8,0) | G8: =IFERROR(SUMIFS('Raw Data'!$L:$L,'Raw Data'!$C:$C,"Treatment",'Raw Data'!$F:$F,"Referral")/C8,0) | H8: =IFERROR(AVERAGEIFS('Raw Data'!$P:$P,'Raw Data'!$C:$C,"Control",'Raw Data'!$F:$F,"Referral"),0) | I8: =IFERROR(AVERAGEIFS('Raw Data'!$P:$P,'Raw Data'!$C:$C,"Treatment",'Raw Data'!$F:$F,"Referral"),0) | J8: =IF(E8>D8,"Treatment better conversion","Control better/equal conversion")
A9: Social | B9: =COUNTIFS('Raw Data'!$C:$C,"Control",'Raw Data'!$F:$F,"Social") | C9: =COUNTIFS('Raw Data'!$C:$C,"Treatment",'Raw Data'!$F:$F,"Social") | D9: =IFERROR(COUNTIFS('Raw Data'!$C:$C,"Control",'Raw Data'!$F:$F,"Social",'Raw Data'!$K:$K,1)/B9,0) | E9: =IFERROR(COUNTIFS('Raw Data'!$C:$C,"Treatment",'Raw Data'!$F:$F,"Social",'Raw Data'!$K:$K,1)/C9,0) | F9: =IFERROR(SUMIFS('Raw Data'!$L:$L,'Raw Data'!$C:$C,"Control",'Raw Data'!$F:$F,"Social")/B9,0) | G9: =IFERROR(SUMIFS('Raw Data'!$L:$L,'Raw Data'!$C:$C,"Treatment",'Raw Data'!$F:$F,"Social")/C9,0) | H9: =IFERROR(AVERAGEIFS('Raw Data'!$P:$P,'Raw Data'!$C:$C,"Control",'Raw Data'!$F:$F,"Social"),0) | I9: =IFERROR(AVERAGEIFS('Raw Data'!$P:$P,'Raw Data'!$C:$C,"Treatment",'Raw Data'!$F:$F,"Social"),0) | J9: =IF(E9>D9,"Treatment better conversion","Control better/equal conversion")
A12: Student Note
A13: This segment sheet compares at least three metrics by group: paid conversion rate, average revenue per user, and average engagement score.

Sheet Plan Type Analysis
A1: Plan Type Analysis - Segment Level Metrics
A3: Plan Type | B3: Control Users | C3: Treatment Users | D3: Control Paid Conversion Rate | E3: Treatment Paid Conversion Rate | F3: Control ARPU | G3: Treatment ARPU | H3: Control Avg Engagement | I3: Treatment Avg Engagement | J3: Quick Comment
A4: Basic | B4: =COUNTIFS('Raw Data'!$C:$C,"Control",'Raw Data'!$G:$G,"Basic") | C4: =COUNTIFS('Raw Data'!$C:$C,"Treatment",'Raw Data'!$G:$G,"Basic") | D4: =IFERROR(COUNTIFS('Raw Data'!$C:$C,"Control",'Raw Data'!$G:$G,"Basic",'Raw Data'!$K:$K,1)/B4,0) | E4: =IFERROR(COUNTIFS('Raw Data'!$C:$C,"Treatment",'Raw Data'!$G:$G,"Basic",'Raw Data'!$K:$K,1)/C4,0) | F4: =IFERROR(SUMIFS('Raw Data'!$L:$L,'Raw Data'!$C:$C,"Control",'Raw Data'!$G:$G,"Basic")/B4,0) | G4: =IFERROR(SUMIFS('Raw Data'!$L:$L,'Raw Data'!$C:$C,"Treatment",'Raw Data'!$G:$G,"Basic")/C4,0) | H4: =IFERROR(AVERAGEIFS('Raw Data'!$P:$P,'Raw Data'!$C:$C,"Control",'Raw Data'!$G:$G,"Basic"),0) | I4: =IFERROR(AVERAGEIFS('Raw Data'!$P:$P,'Raw Data'!$C:$C,"Treatment",'Raw Data'!$G:$G,"Basic"),0) | J4: =IF(E4>D4,"Treatment better conversion","Control better/equal conversion")
A5: Free | B5: =COUNTIFS('Raw Data'!$C:$C,"Control",'Raw Data'!$G:$G,"Free") | C5: =COUNTIFS('Raw Data'!$C:$C,"Treatment",'Raw Data'!$G:$G,"Free") | D5: =IFERROR(COUNTIFS('Raw Data'!$C:$C,"Control",'Raw Data'!$G:$G,"Free",'Raw Data'!$K:$K,1)/B5,0) | E5: =IFERROR(COUNTIFS('Raw Data'!$C:$C,"Treatment",'Raw Data'!$G:$G,"Free",'Raw Data'!$K:$K,1)/C5,0) | F5: =IFERROR(SUMIFS('Raw Data'!$L:$L,'Raw Data'!$C:$C,"Control",'Raw Data'!$G:$G,"Free")/B5,0) | G5: =IFERROR(SUMIFS('Raw Data'!$L:$L,'Raw Data'!$C:$C,"Treatment",'Raw Data'!$G:$G,"Free")/C5,0) | H5: =IFERROR(AVERAGEIFS('Raw Data'!$P:$P,'Raw Data'!$C:$C,"Control",'Raw Data'!$G:$G,"Free"),0) | I5: =IFERROR(AVERAGEIFS('Raw Data'!$P:$P,'Raw Data'!$C:$C,"Treatment",'Raw Data'!$G:$G,"Free"),0) | J5: =IF(E5>D5,"Treatment better conversion","Control better/equal conversion")
A6: Premium | B6: =COUNTIFS('Raw Data'!$C:$C,"Control",'Raw Data'!$G:$G,"Premium") | C6: =COUNTIFS('Raw Data'!$C:$C,"Treatment",'Raw Data'!$G:$G,"Premium") | D6: =IFERROR(COUNTIFS('Raw Data'!$C:$C,"Control",'Raw Data'!$G:$G,"Premium",'Raw Data'!$K:$K,1)/B6,0) | E6: =IFERROR(COUNTIFS('Raw Data'!$C:$C,"Treatment",'Raw Data'!$G:$G,"Premium",'Raw Data'!$K:$K,1)/C6,0) | F6: =IFERROR(SUMIFS('Raw Data'!$L:$L,'Raw Data'!$C:$C,"Control",'Raw Data'!$G:$G,"Premium")/B6,0) | G6: =IFERROR(SUMIFS('Raw Data'!$L:$L,'Raw Data'!$C:$C,"Treatment",'Raw Data'!$G:$G,"Premium")/C6,0) | H6: =IFERROR(AVERAGEIFS('Raw Data'!$P:$P,'Raw Data'!$C:$C,"Control",'Raw Data'!$G:$G,"Premium"),0) | I6: =IFERROR(AVERAGEIFS('Raw Data'!$P:$P,'Raw Data'!$C:$C,"Treatment",'Raw Data'!$G:$G,"Premium"),0) | J6: =IF(E6>D6,"Treatment better conversion","Control better/equal conversion")
A9: Student Note
A10: This segment sheet compares at least three metrics by group: paid conversion rate, average revenue per user, and average engagement score.

Sheet Raw Data
A1: user_id | B1: signup_date | C1: experiment_group | D1: region | E1: device_type | F1: traffic_source | G1: plan_type | H1: visited_landing_page | I1: started_trial | J1: completed_onboarding | K1: converted_to_paid | L1: revenue_30d | M1: support_tickets_30d | N1: refund_requested | O1: days_to_convert | P1: engagement_score
A2: USR-100001 | B2: 45732 | C2: Control | D2: North | E2: Desktop | F2: Email | G2: Basic | H2: 0 | I2: 0 | J2: 0 | K2: 0 | L2: 0 | M2: 0 | N2: 0 | P2: 45.7
A3: USR-100002 | B3: 45724 | C3: Control | D3: West | E3: Mobile | F3: Organic | G3: Free | H3: 1 | I3: 0 | J3: 0 | K3: 0 | L3: 0 | M3: 0 | N3: 0 | P3: 48.6
A4: USR-100003 | B4: 45771 | C4: Control | D4: East | E4: Mobile | F4: Paid Search | G4: Premium | H4: 1 | I4: 0 | J4: 0 | K4: 0 | L4: 0 | M4: 1 | N4: 0 | P4: 35.4
A5: USR-100004 | B5: 45781 | C5: Control | D5: South | E5: Mobile | F5: Email | G5: Basic | H5: 1 | I5: 0 | J5: 0 | K5: 0 | L5: 0 | M5: 0 | N5: 0 | P5: 64.6
A6: USR-100005 | B6: 45700 | C6: Control | D6: North | E6: Tablet | F6: Organic | G6: Free | H6: 0 | I6: 0 | J6: 0 | K6: 0 | L6: 0 | M6: 0 | N6: 0 | P6: 66.6
A7: USR-100006 | B7: 45685 | C7: Control | D7: East | E7: Mobile | F7: Organic | G7: Premium | H7: 1 | I7: 0 | J7: 0 | K7: 0 | L7: 0 | M7: 0 | N7: 0 | P7: 40.8
A8: USR-100007 | B8: 45755 | C8: Control | D8: East | E8: Mobile | F8: Paid Search | G8: Basic | H8: 1 | I8: 1 | J8: 0 | K8: 0 | L8: 0 | M8: 0 | N8: 0 | P8: 57.1
A9: USR-100008 | B9: 45794 | C9: Control | D9: South | E9: Mobile | F9: Paid Search | G9: Free | H9: 0 | I9: 0 | J9: 0 | K9: 0 | L9: 0 | M9: 0 | N9: 0 | P9: 36.4
A10: USR-100009 | B10: 45711 | C10: Control | D10: South | E10: Tablet | F10: Referral | G10: Basic | H10: 0 | I10: 0 | J10: 0 | K10: 0 | L10: 0 | M10: 0 | N10: 0 | P10: 55.4
A11: USR-100010 | B11: 45806 | C11: Control | D11: West | E11: Desktop | F11: Social | G11: Free | H11: 1 | I11: 0 | J11: 0 | K11: 0 | L11: 0 | M11: 0 | N11: 0 | P11: 57.3
A12: USR-100011 | B12: 45777 | C12: Control | D12: East | E12: Mobile | F12: Paid Search | G12: Basic | H12: 1 | I12: 1 | J12: 1 | K12: 0 | L12: 0 | M12: 0 | N12: 0 | P12: 63.6
A13: USR-100012 | B13: 45732 | C13: Control | D13: East | E13: Mobile | F13: Social | G13: Premium | H13: 1 | I13: 1 | J13: 1 | K13: 0 | L13: 0 | M13: 1 | N13: 0 | P13: 80.4
... A60: USR-100059 | B60: 45761 | C60: Control | D60: North | E60: Mobile | F60: Social | G60: Free | H60: 0 | I60: 0 | J60: 0 | K60: 0 | L60: 0 | M60: 2 | N60: 0 | P60: 48.9
A61: USR-100060 | B61: 45658 | C61: Control | D61: West | E61: Mobile | F61: Social | G61: Free | H61: 1 | I61: 1 | J61: 1 | K61: 1 | L61: 240.42 | M61: 0 | N61: 0 | O61: 16 | P61: 56.5
A62: USR-100061 | B62: 45749 | C62: Control | D62: South | E62: Mobile | F62: Referral | G62: Free | H62: 1 | I62: 0 | J62: 0 | K62: 0 | L62: 0 | M62: 0 | N62: 0 | P62: 53.7
A63: USR-100062 | B63: 45745 | C63: Control | D63: North | E63: Mobile | F63: Social | G63: Premium | H63: 0 | I63: 0 | J63: 0 | K63: 0 | L63: 0 | M63: 0 | N63: 0 | P63: 62.2
A64: USR-100063 | B64: 45792 | C64: Control | D64: South | E64: Desktop | F64: Organic | G64: Free | H64: 1 | I64: 0 | J64: 0 | K64: 0 | L64: 0 | M64: 0 | N64: 0 | P64: 50.2
A65: USR-100064 | B65: 45758 | C65: Control | D65: North | E65: Mobile | F65: Organic | G65: Basic | H65: 1 | I65: 0 | J65: 0 | K65: 0 | L65: 0 | M65: 0 | N65: 0 | P65: 74.3
A66: USR-100065 | B66: 45723 | C66: Control | D66: South | E66: Desktop | F66: Paid Search | G66: Free | H66: 1 | I66: 0 | J66: 0 | K66: 0 | L66: 0 | M66: 0 | N66: 0 | P66: 58
A67: USR-100066 | B67: 45807 | C67: Control | D67: South | E67: Mobile | F67: Organic | G67: Free | H67: 0 | I67: 0 | J67: 0 | K67: 0 | L67: 0 | M67: 0 | N67: 0 | P67: 46.7
A68: USR-100067 | B68: 45664 | C68: Control | D68: South | E68: Desktop | F68: Organic | G68: Premium | H68: 1 | I68: 0 | J68: 0 | K68: 0 | L68: 0 | M68: 1 | N68: 0 | P68: 49.6
A69: USR-100068 | B69: 45785 | C69: Control | D69: West | E69: Mobile | F69: Social | G69: Free | H69: 0 | I69: 0 | J69: 0 | K69: 0 | L69: 0 | M69: 0 | N69: 0 | P69: 60.4
A70: USR-100069 | B70: 45735 | C70: Control | D70: East | E70: Desktop | F70: Email | G70: Free | H70: 1 | I70: 1 | J70: 1 | K70: 0 | L70: 0 | M70: 0 | N70: 0 | P70: 55.3
A71: USR-100070 | B71: 45793 | C71: Control | D71: North | E71: Desktop | F71: Organic | G71: Free | H71: 0 | I71: 0 | J71: 0 | K71: 0 | L71: 0 | M71: 0 | N71: 0 | P71: 56.2
A72: USR-100071 | B72: 45724 | C72: Control | D72: West | E72: Mobile | F72: Email | G72: Free | H72: 0 | I72: 0 | J72: 0 | K72: 0 | L72: 0 | M72: 0 | N72: 0 | P72: 29.4
A73: USR-100072 | B73: 45724 | C73: Control | D73: East | E73: Mobile | F73: Email | G73: Free | H73: 1 | I73: 0 | J73: 0 | K73: 0 | L73: 0 | M73: 0 | N73: 0 | P73: 54.2
... A79: USR-100078 | B79: 45673 | C79: Control | D79: North | E79: Mobile | F79: Organic | G79: Free | H79: 0 | I79: 0 | J79: 0 | K79: 0 | L79: 0 | M79: 2 | N79: 0 | P79: 48.4
A80: USR-100079 | B80: 45708 | C80: Control | D80: West | E80: Desktop | F80: Organic | G80: Free | H80: 1 | I80: 1 | J80: 1 | K80: 1 | L80: 457.51 | M80: 0 | N80: 0 | O80: 7 | P80: 38
A81: USR-100080 | B81: 45798 | C81: Control | D81: East | E81: Mobile | F81: Social | G81: Free | H81: 1 | I81: 0 | J81: 0 | K81: 0 | L81: 0 | M81: 0 | N81: 0 | P81: 44.2
A82: USR-100081 | B82: 45785 | C82: Control | D82: South | E82: Mobile | F82: Organic | G82: Free | H82: 1 | I82: 1 | J82: 1 | K82: 0 | L82: 0 | M82: 0 | N82: 0 | P82: 81.2
A83: USR-100082 | B83: 45724 | C83: Control | D83: South | E83: Mobile | F83: Referral | G83: Free | H83: 1 | I83: 1 | J83: 0 | K83: 0 | L83: 0 | M83: 0 | N83: 0 | P83: 63.8
A84: USR-100083 | B84: 45748 | C84: Control | D84: South | E84: Desktop | F84: Email | G84: Free | H84: 0 | I84: 0 | J84: 0 | K84: 0 | L84: 0 | M84: 0 | N84: 0 | P84: 64.7
A85: USR-100084 | B85: 45719 | C85: Control | D85: West | E85: Mobile | F85: Social | G85: Basic | H85: 0 | I85: 0 | J85: 0 | K85: 0 | L85: 0 | M85: 0 | N85: 0 | P85: 60.4
A86: USR-100085 | B86: 45763 | C86: Control | D86: South | E86: Mobile | F86: Paid Search | G86: Free | H86: 0 | I86: 0 | J86: 0 | K86: 0 | L86: 0 | M86: 0 | N86: 0 | P86: 66.6
A87: USR-100086 | B87: 45666 | C87: Control | D87: North | E87: Desktop | F87: Organic | G87: Free | H87: 1 | I87: 0 | J87: 0 | K87: 0 | L87: 0 | M87: 0 | N87: 0 | P87: 50.9
A88: USR-100087 | B88: 45679 | C88: Control | D88: West | E88: Desktop | F88: Social | G88: Basic | H88: 0 | I88: 0 | J88: 0 | K88: 0 | L88: 0 | M88: 0 | N88: 0 | P88: 51
A89: USR-100088 | B89: 45777 | C89: Control | D89: South | E89: Mobile | F89: Email | G89: Premium | H89: 0 | I89: 0 | J89: 0 | K89: 0 | L89: 0 | M89: 0 | N89: 0 | P89: 65.8
A90: USR-100089 | B90: 45772 | C90: Control | D90: North | E90: Mobile | F90: Referral | G90: Basic | H90: 1 | I90: 0 | J90: 0 | K90: 0 | L90: 0 | M90: 0 | N90: 0 | P90: 61.8
A91: USR-100090 | B91: 45689 | C91: Control | D91: North | E91: Mobile | F91: Organic | G91: Basic | H91: 1 | I91: 0 | J91: 0 | K91: 0 | L91: 0 | M91: 0 | N91: 0 | P91: 54.5
...
